Workbook

Sheet Checklist
A1: # | B1: Checkpoint | C1: Component | D1: Week | E1: Level | F1: Task | G1: Command / files | H1: Expected result | I1: Done | J1: Date | K1: Checked by | L1: Notes
A2: 1 | B2: 0 | C2: Own the lab | D2: 1 | E2: Setup | F2: git init && git add -A && git commit -m "baseline": every experiment can be undone with git checkout . | I2: Yes
A3: 2 | B3: 0 | C3: Own the lab | D3: 1 | E3: Setup | F3: Start / stop / status: docker compose up -d · docker compose down · docker compose ps (38 running) | I3: Yes
A4: 3 | B4: 0 | C4: Own the lab | D4: 1 | E4: Setup | F4: Logs: docker compose logs -f router-1 · docker logs --since 5m hal-control | I4: Yes
A5: 4 | B5: 0 | C5: Own the lab | D5: 1 | E5: Setup | F5: Deploy one service: docker compose up -d --build --no-deps control | I5: Yes
A6: 5 | B6: 0 | C6: Own the lab | D6: 1 | E6: Setup | F6: Read How Every Part Works once, end to end | I6: Yes
A7: 6 | B7: 0 | C7: Own the lab | D7: 1 | E7: Pass | F7: Restart the whole lab from zero and reach "audit all 0" without help. | I7: Yes
A8: 7 | B8: 1 | C8: HAProxy | D8: 1 | E8: 1 Explain | F8: Answer in your own words: - Why round robin? - What do fall 2 rise 2 mean? - What do retries and redispatch do? | I8: Yes | J8: 46318 | L8: ROUND ROBIN -- ONE BY ONE -----CHECK TWO TIME BEFORE ANSWERING ------RETRY MEANS AUTOMATICALLY RETRYING BEFORE INFORMING USER AND REDISPATCH IS SWITCHING TO ANOTHER API
A9: 8 | B9: 1 | C9: HAProxy | D9: 1 | E9: 2 Inspect | F9: Run and read the output | G9: docker exec hal-haproxy-1 sh -c "wget -qO- 'http://127.0.0.1:8404/stats;csv' | cut -d, -f1,2,18" | I9: Yes
A10: 9 | B10: 1 | C10: HAProxy | D10: 1 | E10: 3 Break | F10: Write your prediction first, then run | G10: docker stop hal-api-2 | H10: marked DOWN within ~2 s; traders unaffected; audit 0 | I10: Yes
A11: 10 | B11: 1 | C11: HAProxy | D11: 1 | E11: 4 Read | F11: Explain each file / function | G11: config/haproxy-edge.cfg (every line) | I11: Yes | L11: Header comment # Edge load balancer (haproxy-1 in Azure zone 1, haproxy-2 in Azure zone 2). Traders know both addresses. A comment (#), ignored by HAProxy. It says this one file is used by both HAProxys. global: settings for the whole HAProxy process Line Meaning global starts the process-wide section maxconn 2000 at most 2000 connections open at the same time; more wait in a queue. This protects HAProxy from overload defaults: settings every section below inherits Line Meaning defaults starts the defaults section mode http work at layer 7: read each HTTP request (path, status). Needed for health checks by URL and for retrying requests timeout connect 2s if a TCP connection to an API can't be made within 2 s, treat it as failed timeout client 30s if a trader's connection is silent for 30 s, close it timeout server 10s how long to wait for an API to answer (the backend below lowers this to 5 s) option http-server-close close the HAProxy→API connection after each response, so every request can go to a different API and retries can use a fresh one resolvers docker: how to turn names like api-1 into IP addresses Line Meaning resolvers docker defines a DNS setup named "docker" nameserver dns 127.0.0.11:53 ask Docker's built-in DNS (always at 127.0.0.11 inside a container) resolve_retries 2 if DNS doesn't answer, ask up to 2 times timeout resolve 1s look the names up again every 1 s, so a restarted API with a new IP is found quickly hold valid 2s keep using a good answer for 2 s hold nx 1s if DNS says "no such name" (the container is gone), keep the old IP only 1 s more, then treat the server as unreachable hold other 1s the same for other DNS errors frontend web: the door traders connect to Line Meaning frontend web a listener named "web" (that's the web,FRONTEND,OPEN you saw) bind :8080 listen on port 8080 on all of this container's IPs default_backend apis send every request to the group named "apis" backend apis: the group of API servers and how to use them Line Meaning backend apis the group named "apis" balance roundrobin take turns: api-1, api-2, api-3, api-4, api-1… option httpchk GET /health the health check is an HTTP GET /health; any 2xx/3xx answer = healthy. An API that is shutting down answers 503, so it's taken out # Retry on another… (2 comment lines) explains why retrying is safe: orders carry a client_ref, so a resend can't make a second order retries 2 a failed request is tried up to 2 more times retry-on conn-failure empty-response response-timeout retry only when: it couldn't connect, the API closed without answering, or it didn't answer in time option redispatch 1 send every retry to a different API (the 1 = on every retry) timeout server 5s in this group, an API must answer within 5 s (overrides the 10 s default) default-server inter 1s fall 2 rise 2 resolvers docker init-addr none settings for each server line below: health check every 1 s; 2 fails = DOWN; 2 OKs = UP; find the IP through the "docker" resolver; init-addr none = start even if an API's name can't be found yet (e.g. it's still booting) server api-1 api-1:8000 check an API server: name api-1, address api-1 port 8000, check = health-check it server api-2 … / api-3 / api-4 the same for the other three listen stats: the status page Line Meaning listen stats listen = a frontend and backend in one; named "stats" bind :8404 listen on port 8404 stats enable turn on HAProxy's built-in status page stats uri /stats it's at /stats (you read it with /stats;csv) stats refresh 2s the page auto-refreshes every 2 s in a browser In one line: traders connect on 8080, HAProxy takes turns across 4 APIs it health-checks every second, retries a failed request on another API, finds the APIs by name through Docker's DNS, and shows its view on 8404/stats.
A12: 11 | B12: 1 | C12: HAProxy | D12: 1 | E12: 5 Change | F12: Set inter 1s → inter 3s, redeploy, measure the slower detection, revert. | H12: Audit stays 0; revert with git | I12: Yes
A13: 12 | B13: 2 | C13: API servers | D13: 1 | E13: 1 Explain | F13: Answer in your own words: - Why does ONE transaction write the order and the outbox? - What does client_ref protect against? - Why is the login token stateless? | I13: Yes
A14: 13 | B14: 2 | C14: API servers | D14: 1 | E14: 2 Inspect | F14: Run and read the output | G14: docker logs --since 2m hal-api-1 | I14: Yes
A15: 14 | B15: 2 | C15: API servers | D15: 1 | E15: 3 Break | F15: Write your prediction first, then run | G15: docker kill hal-api-3 | H15: a few trader errors in the last 10 s, all recovered by retry; lost = 0 | I15: Yes
A16: 15 | B16: 2 | C16: API servers | D16: 1 | E16: 4 Read | F16: Explain each file / function | G16: app/api.py: place_order, cancel_order, make_token / verify_token, best_effort, tick_loop, main (drain)
A17: 16 | B17: 2 | C17: API servers | D17: 1 | E17: 5 Change | F17: Lower STALE_AFTER in app/common.py from 3 s to 1 s; watch "refused (stale)" rise; revert. | H17: Audit stays 0; revert with git
A18: 17 | B18: 3 | C18: PostgreSQL + Patroni + etcd | D18: 2 | E18: 1 Explain | F18: Answer in your own words: - Why quorum commit? - Why a 20 s leader-key TTL? - Why refuse to run with one node left? - What does pg_rewind do?
A19: 18 | B19: 3 | C19: PostgreSQL + Patroni + etcd | D19: 2 | E19: 2 Inspect | F19: Run and read the output | G19: docker exec hal-pg-1 curl -s localhost:8008/cluster docker exec hal-etcd-1 etcdctl endpoint status --cluster -w table docker exec -it hal-pg-1 psql -U postgres -d trading (explore every table in app/schema.sql)
A20: 19 | B20: 3 | C20: PostgreSQL + Patroni + etcd | D20: 2 | E20: 3 Break | F20: Write your prediction first, then run | G20: docker kill hal-pg-1 # use the node the inspect command shows as leader | H20: ~20 s of "try again", then a new leader; lost = 0
A21: 20 | B21: 3 | C21: PostgreSQL + Patroni + etcd | D21: 2 | E21: 3 Break | F21: Write your prediction first, then run | G21: docker stop hal-pg-2 hal-pg-3 | H21: DATABASE DOWN and NO promotion: explain why
A22: 21 | B22: 3 | C22: PostgreSQL + Patroni + etcd | D22: 2 | E22: 3 Break | F22: Write your prediction first, then run | G22: docker kill hal-etcd-3 # use the endpoint with IS LEADER = true | H22: new etcd leader in ~2 s; the database keeps working
A23: 22 | B23: 3 | C23: PostgreSQL + Patroni + etcd | D23: 2 | E23: 4 Read | F23: Explain each file / function | G23: images/postgres/patroni.yml (every line) images/postgres/post_bootstrap.sh images/postgres/pgbackrest.conf
A24: 23 | B24: 3 | C24: PostgreSQL + Patroni + etcd | D24: 2 | E24: 5 Change | F24: Restore drill: restore the latest backup into a spare test container (never the live cluster) and state the RPO. | H24: Audit stays 0; revert with git
A25: 24 | B25: 4 | C25: PgBouncer | D25: 2 | E25: 1 Explain | F25: Answer in your own words: - Transaction vs session pooling - Why prepared statements are disabled - How the built-in HAProxy follows the leader
A26: 25 | B26: 4 | C26: PgBouncer | D26: 2 | E26: 2 Inspect | F26: Run and read the output | G26: docker exec -e PGPASSWORD=apppass hal-pg-1 psql -h pgbouncer-1 -p 6432 -U app pgbouncer -c "show pools"
A27: 26 | B27: 4 | C27: PgBouncer | D27: 2 | E27: 3 Break | F27: Write your prediction first, then run | G27: docker stop hal-pgbouncer-1 | H27: apps switch to pgbouncer-2; nothing noticed
A28: 27 | B28: 4 | C28: PgBouncer | D28: 2 | E28: 4 Read | F28: Explain each file / function | G28: images/pgbouncer/pgbouncer.ini images/pgbouncer/haproxy-pg.cfg app/common.py: dsn()
A29: 28 | B29: 4 | C29: PgBouncer | D29: 2 | E29: 5 Change | F29: Set default_pool_size 15 → 3; watch cl_waiting rise under load; revert. | H29: Audit stays 0; revert with git
A30: 29 | B30: 5 | C30: Outbox + Relay | D30: 2 | E30: 1 Explain | F30: Answer in your own words: - What breaks if the API publishes to Kafka directly? - Why FOR UPDATE SKIP LOCKED? - Why can a message be sent twice, and why is that fine?
A31: 30 | B31: 5 | C31: Outbox + Relay | D31: 2 | E31: 2 Inspect | F31: Run and read the output | G31: docker exec hal-pg-1 psql -U postgres -d trading -c "select count(*) filter (where published_at is null) unsent, count(*) total from outbox"
A32: 31 | B32: 5 | C32: Outbox + Relay | D32: 2 | E32: 3 Break | F32: Write your prediction first, then run | G32: docker stop hal-relay-1 hal-relay-2 # 30 s later: docker start hal-relay-1 hal-relay-2 | H32: unsent grows, then drains to ~0; nothing lost
A33: 32 | B33: 5 | C33: Outbox + Relay | D33: 2 | E33: 4 Read | F33: Explain each file / function | G33: app/relay.py (whole file)
A34: 33 | B34: 5 | C34: Outbox + Relay | D34: 2 | E34: 5 Change | F34: Write an outbox cleanup job: delete published rows older than 1 day (the table is 728 MB today). | H34: Audit stays 0; revert with git
A35: 34 | B35: 6 | C35: Kafka | D35: 2 | E35: 1 Explain | F35: Answer in your own words: - Partition, leader, ISR, consumer group, offset - acks=all + min.insync.replicas=2 - Why are the price lines single-copy on purpose?
A36: 35 | B36: 6 | C36: Kafka | D36: 2 | E36: 2 Inspect | F36: Run and read the output | G36: docker exec hal-kafka-1 /opt/kafka/bin/kafka-topics.sh --bootstrap-server localhost:9092 --describe --topic orders.submit docker exec hal-kafka-1 /opt/kafka/bin/kafka-consumer-groups.sh --bootstrap-server localhost:9092 --describe --group notify-bridge
A37: 36 | B37: 6 | C37: Kafka | D37: 2 | E37: 3 Break | F37: Write your prediction first, then run | G37: docker kill hal-kafka-1 # the broker leading the most partitions | H37: new leaders in 0.5–3 s; price gap < 0.2 s
A38: 37 | B38: 6 | C38: Kafka | D38: 2 | E38: 3 Break | F38: Write your prediction first, then run | G38: docker stop hal-kafka-1 hal-kafka-2 | H38: producers stop (ISR < 2), outbox backlog grows, nothing lost
A39: 38 | B39: 6 | C39: Kafka | D39: 2 | E39: 4 Read | F39: Explain each file / function | G39: docker-compose.yml (Kafka environment) app/common.py: producer_conf, TICK_TOPICS app/control.py: bootstrap (topic creation)
A40: 39 | B40: 6 | C40: Kafka | D40: 2 | E40: 5 Change | F40: Create a test topic (3 partitions, RF 3), produce to it and read it back with the console consumer. | H40: Audit stays 0; revert with git
...

Sheet Progress
A1: Checkpoint | B1: Component | C1: Tasks | D1: Done | E1: % done
A2: How to use: fill Done (Yes/No), Date and Checked by on the Checklist sheet; this sheet updates itself.
A3: 0 | B3: Own the lab | C3: =COUNTIF(Checklist!$B:$B,0) -> 6 | D3: =COUNTIFS(Checklist!$B:$B,0,Checklist!$I:$I,"Yes") -> 6 | E3: =IF(C3=0,0,D3/C3) -> 1
A4: 1 | B4: HAProxy | C4: =COUNTIF(Checklist!$B:$B,1) -> 5 | D4: =COUNTIFS(Checklist!$B:$B,1,Checklist!$I:$I,"Yes") -> 5 | E4: =IF(C4=0,0,D4/C4) -> 1
A5: 2 | B5: API servers | C5: =COUNTIF(Checklist!$B:$B,2) -> 5 | D5: =COUNTIFS(Checklist!$B:$B,2,Checklist!$I:$I,"Yes") -> 3 | E5: =IF(C5=0,0,D5/C5) -> 0.6
A6: 3 | B6: PostgreSQL + Patroni + etcd | C6: =COUNTIF(Checklist!$B:$B,3) -> 7 | D6: =COUNTIFS(Checklist!$B:$B,3,Checklist!$I:$I,"Yes") -> 0 | E6: =IF(C6=0,0,D6/C6) -> 0
A7: 4 | B7: PgBouncer | C7: =COUNTIF(Checklist!$B:$B,4) -> 5 | D7: =COUNTIFS(Checklist!$B:$B,4,Checklist!$I:$I,"Yes") -> 0 | E7: =IF(C7=0,0,D7/C7) -> 0
A8: 5 | B8: Outbox + Relay | C8: =COUNTIF(Checklist!$B:$B,5) -> 5 | D8: =COUNTIFS(Checklist!$B:$B,5,Checklist!$I:$I,"Yes") -> 0 | E8: =IF(C8=0,0,D8/C8) -> 0
A9: 6 | B9: Kafka | C9: =COUNTIF(Checklist!$B:$B,6) -> 6 | D9: =COUNTIFS(Checklist!$B:$B,6,Checklist!$I:$I,"Yes") -> 0 | E9: =IF(C9=0,0,D9/C9) -> 0
A10: 7 | B10: Order router | C10: =COUNTIF(Checklist!$B:$B,7) -> 6 | D10: =COUNTIFS(Checklist!$B:$B,7,Checklist!$I:$I,"Yes") -> 0 | E10: =IF(C10=0,0,D10/C10) -> 0
A11: 8 | B11: Feed + price lines | C11: =COUNTIF(Checklist!$B:$B,8) -> 5 | D11: =COUNTIFS(Checklist!$B:$B,8,Checklist!$I:$I,"Yes") -> 0 | E11: =IF(C11=0,0,D11/C11) -> 0
A12: 9 | B12: Bridge → RabbitMQ → Worker | C12: =COUNTIF(Checklist!$B:$B,9) -> 6 | D12: =COUNTIFS(Checklist!$B:$B,9,Checklist!$I:$I,"Yes") -> 0 | E12: =IF(C12=0,0,D12/C12) -> 0
A13: 10 | B13: Redis + Sentinel | C13: =COUNTIF(Checklist!$B:$B,10) -> 6 | D13: =COUNTIFS(Checklist!$B:$B,10,Checklist!$I:$I,"Yes") -> 0 | E13: =IF(C13=0,0,D13/C13) -> 0
A14: 11 | B14: Control, audit and dashboard | C14: =COUNTIF(Checklist!$B:$B,11) -> 5 | D14: =COUNTIFS(Checklist!$B:$B,11,Checklist!$I:$I,"Yes") -> 0 | E14: =IF(C14=0,0,D14/C14) -> 0
A15: Final | B15: Guarantee | C15: =COUNTIF(Checklist!$B:$B,"Final") -> 7 | D15: =COUNTIFS(Checklist!$B:$B,"Final",Checklist!$I:$I,"Yes") -> 0 | E15: =IF(C15=0,0,D15/C15) -> 0
A16: Total | C16: =SUM(C3:C15) -> 74 | D16: =SUM(D3:D15) -> 14 | E16: =IF(C16=0,0,D16/C16) -> 0.18918919
